Workbook

Sheet Cover Page
A1: Orthopedics Service Line Budget & Performance Model (HOPD) FY2026 | Margin, Capacity, Break-Even, Productivity & Payor Mix
B6: Content
B8: Detailed Budget
B9: Procedure Margin
B10: Capacity
B11: Break-Even Analysis
B12: Productivity
B13: Payor Mix
B14: Analysis Input
B15: Assumptions
B16: Detail Catalog

Sheet Annual Budget
B1: Orthopedics Service Line — Operating Budget Summary FY2026 Budget vs FY2025 Actual | $000s (USD)
C6: FY2025 (Actual) | D6: FY2026 (Budget) | E6: ∆$ | F6: ∆%P
B7: Volume
B8: Clinic Visits | C8: 23100 | D8: =Assumption!C40 -> 22000 | F8: =(D8-C8)/C8 -> -0.047619048
B9: Surgical Cases | C9: 3350 | D9: =Assumption!G11 -> 3455 | F9: =(D9-C9)/C9 -> 0.031343284
B10: Inpatient | C10: 922 | D10: =Assumption!G12 -> 975 | F10: =(D10-C10)/C10 -> 0.057483731
B11: Outpatient | C11: =C9-C10 -> 2428 | D11: =D9-D10 -> 2480 | F11: =(D11-C11)/C11 -> 0.021416804
B13: Revenue
B14: Surgical Revenue | C14: 44688960 | D14: =Assumption!G39 -> 45631400 | E14: =D14-C14 -> 942439.7 | F14: =(D14-C14)/C14 -> 0.021088871
B15: Clinic Revenue | C15: 8955313 | D15: =Assumption!G43 -> 8790000 | E15: =D15-C15 -> -165313 | F15: =(D15-C15)/C15 -> -0.018459768
B16: Total Revenue | C16: =SUM(C14:C15) -> 53644273 | D16: =SUM(D14:D15) -> 54421400 | E16: =D16-C16 -> 777126.7 | F16: =(D16-C16)/C16 -> 0.014486667
B18: Expenses
B19: Salaries & Benefits | C19: 7412258 | D19: ='Detailed Budget'!H35 -> 7608810.9 | E19: =(D19-C19) -> 196552.95 | F19: =(D19-C19)/C19 -> 0.026517284
B20: Medical Supplies | C20: 9563221 | D20: ='Detailed Budget'!H42 -> 10604175 | E20: =(D20-C20) -> 1040954 | F20: =(D20-C20)/C20 -> 0.10884973
B21: Purcahsed Services & Overhead | C21: 34112369 | D21: ='Detailed Budget'!H53 -> 34461650 | E21: =(D21-C21) -> 349281 | F21: =(D21-C21)/C21 -> 0.010239131
B22: Depreciation | C22: 670000 | D22: ='Detailed Budget'!H52 -> 670000 | E22: =-(D22-C22) -> 0 | F22: =(D22-C22)/C22 -> 0
B23: Total Expenses | C23: =SUM(C19:C22) -> 51757848 | D23: ='Detailed Budget'!H56 -> 52674636 | E23: =(D23-C23) -> 916787.95 | F23: =(D23-C23)/C23 -> 0.017713023
B25: Net Income (Loss) | C25: =C16-C23 -> 1886425 | D25: ='Detailed Budget'!H57 -> 1746763.8 | E25: =(D25-C25) -> -139661.25 | F25: =-(D25-C25)/C25 -> 0.07403488
B26: Net Operating Margin | C26: =C25/C16 -> 0.03516545 | D26: ='Detailed Budget'!H58 -> 0.032097002 | F26: =D26-C26 -> -0.0030684484

Sheet Detailed Budget
B4: GL Code | C4: Item | D4: Driver | E4: Unit | F4: Annual Volume/FTE | G4: Rate ($)/% | H4: Annual Budget ($) | I4: Jan | J4: Feb | K4: Mar | L4: Apr | M4: May | N4: Jun | O4: Jul | P4: Aug | Q4: Sep | R4: Oct | S4: Nov | T4: Dec
I5: 0.07 | J5: 0.072 | K5: 0.074 | L5: 0.076 | M5: =Assumption!J6 -> 0.085 | N5: 0.095 | O5: 0.098 | P5: 0.1 | Q5: 0.096 | R5: =Assumption!O6 -> 0.083 | S5: =Assumption!P6 -> 0.081 | T5: 0.07 | U5: =SUM(I5:T5) -> 1
B7: Revenue
B8: 4623 | C8: ACL Reconstruction | D8: Volume | E8: Cases | F8: =Assumption!C31 -> 400 | G8: =Assumption!D31 -> 44000 | H8: =Assumption!G31 -> 5572160 | I8: =H8*I$5 -> 390051.2 | J8: =$H$8*J$5 -> 401195.52 | K8: =$H$8*K$5 -> 412339.84 | L8: =$H$8*L$5 -> 423484.16 | M8: =$H$8*M$5 -> 473633.6 | N8: =$H$8*N$5 -> 529355.2 | O8: =$H$8*O$5 -> 546071.68 | P8: =$H$8*P$5 -> 557216 | Q8: =$H$8*Q$5 -> 534927.36 | ... T8: =$H$8*T$5 -> 390051.2
B9: 4158 | C9: Total Knee Replacement | D9: Volume | E9: Cases | F9: =Assumption!C32 -> 300 | G9: =Assumption!D32 -> 82000 | H9: =Assumption!G32 -> 7788360 | I9: =$H$9*I$5 -> 545185.2 | J9: =$H$9*J$5 -> 560761.92 | K9: =$H$9*K$5 -> 576338.64 | L9: =$H$9*L$5 -> 591915.36 | M9: =$H$9*M$5 -> 662010.6 | N9: =$H$9*N$5 -> 739894.2 | O9: =$H$9*O$5 -> 763259.28 | P9: =$H$9*P$5 -> 778836 | ... T9: =$H$9*T$5 -> 545185.2
B10: 4789 | C10: Total Hip Replacement | D10: Volume | E10: Cases | F10: =Assumption!C33 -> 350 | G10: =Assumption!D33 -> 86300 | H10: =Assumption!G33 -> 9562903 | I10: =H10*$I$5 -> 669403.21 | J10: =$H$10*J$5 -> 688529.02 | K10: =$H$10*K$5 -> 707654.82 | L10: =$H$10*L$5 -> 726780.63 | M10: =$H$10*M$5 -> 812846.76 | N10: =$H$10*N$5 -> 908475.79 | O10: =$H$10*O$5 -> 937164.49 | P10: =$H$10*P$5 -> 956290.3 | Q10: =$H$10*Q$5 -> 918038.69 | ... T10: =$H$10*T$5 -> 669403.21
B11: 4556 | C11: Arthroscopy (Other) | D11: Volume | E11: Cases | F11: =Assumption!C34 -> 500 | G11: =Assumption!D34 -> 28100 | H11: =Assumption!G34 -> 4448230 | I11: =H11*$I$5 -> 311376.1 | J11: =$H$11*J$5 -> 320272.56 | K11: =$H$11*K$5 -> 329169.02 | L11: =$H$11*L$5 -> 338065.48 | M11: =$H$11*M$5 -> 378099.55 | N11: =$H$11*N$5 -> 422581.85 | O11: =$H$11*O$5 -> 435926.54 | P11: =$H$11*P$5 -> 444823 | Q11: =$H$11*Q$5 -> 427030.08 | ... T11: =$H$11*T$5 -> 311376.1
B12: 4113 | C12: Rotator Cuff Repair | D12: Volume | E12: Cases | F12: =Assumption!C35 -> 430 | G12: =Assumption!D35 -> 47400 | H12: =Assumption!G35 -> 6452941.2 | I12: =H12*$I$5 -> 451705.88 | J12: =$H$12*J$5 -> 464611.77 | K12: =$H$12*K$5 -> 477517.65 | L12: =$H$12*L$5 -> 490423.53 | M12: =$H$12*M$5 -> 548500 | N12: =$H$12*N$5 -> 613029.41 | O12: =$H$12*O$5 -> 632388.24 | P12: =$H$12*P$5 -> 645294.12 | Q12: =$H$12*Q$5 -> 619482.36 | ... T12: =$H$12*T$5 -> 451705.88
B13: 4187 | C13: Fracture Repair | D13: Volume | E13: Cases | F13: =Assumption!C36 -> 325 | G13: =Assumption!D36 -> 36900 | H13: =Assumption!G36 -> 3796825.5 | I13: =H13*$I$5 -> 265777.78 | J13: =$H$13*J$5 -> 273371.44 | K13: =$H$13*K$5 -> 280965.09 | L13: =$H$13*L$5 -> 288558.74 | M13: =$H$13*M$5 -> 322730.17 | N13: =$H$13*N$5 -> 360698.42 | O13: =$H$13*O$5 -> 372088.9 | P13: =$H$13*P$5 -> 379682.55 | Q13: =$H$13*Q$5 -> 364495.25 | ... T13: =$H$13*T$5 -> 265777.78
B14: 4465 | C14: Carpal Tunnel Release | D14: Volume | E14: Cases | F14: =Assumption!C37 -> 700 | G14: =Assumption!D37 -> 17050 | H14: =Assumption!G37 -> 3778621 | I14: =H14*$I$5 -> 264503.47 | J14: =$H$14*J$5 -> 272060.71 | K14: =$H$14*K$5 -> 279617.95 | L14: =$H$14*L$5 -> 287175.2 | M14: =$H$14*M$5 -> 321182.79 | N14: =$H$14*N$5 -> 358968.99 | O14: =$H$14*O$5 -> 370304.86 | P14: =$H$14*P$5 -> 377862.1 | Q14: =$H$14*Q$5 -> 362747.62 | ... T14: =$H$14*T$5 -> 264503.47
B15: 4002 | C15: Meniscus Repair | D15: Volume | E15: Cases | F15: =Assumption!C38 -> 450 | G15: =Assumption!D38 -> 29700 | H15: =Assumption!G38 -> 4231359 | I15: =H15*$I$5 -> 296195.13 | J15: =$H$15*J$5 -> 304657.85 | K15: =$H$15*K$5 -> 313120.57 | L15: =$H$15*L$5 -> 321583.28 | M15: =$H$15*M$5 -> 359665.52 | N15: =$H$15*N$5 -> 401979.1 | O15: =$H$15*O$5 -> 414673.18 | P15: =$H$15*P$5 -> 423135.9 | Q15: =$H$15*Q$5 -> 406210.46 | ... T15: =$H$15*T$5 -> 296195.13
B16: 4015 | C16: Clinical Visits | D16: Volume | E16: Visit | F16: =Assumption!C40 -> 22000 | G16: =Assumption!F40 -> 300 | H16: =Assumption!G40 -> 6600000 | I16: =H16*$I$5 -> 462000 | J16: =$H$16*J$5 -> 475200 | K16: =$H$16*K$5 -> 488400 | L16: =$H$16*L$5 -> 501600 | M16: =$H$16*M$5 -> 561000 | N16: =$H$16*N$5 -> 627000 | O16: =$H$16*O$5 -> 646800 | P16: =$H$16*P$5 -> 660000 | Q16: =$H$16*Q$5 -> 633600 | ... T16: =$H$16*T$5 -> 462000
B17: 4922 | C17: Imaging Ancillary (X-ray/US/MRI) | D17: Volume | E17: Units | F17: =Assumption!C41 -> 8000 | G17: =Assumption!F41 -> 150 | H17: =Assumption!G41 -> 1200000 | I17: =H17*$I$5 -> 84000 | J17: =$H$17*J$5 -> 86400 | K17: =$H$17*K$5 -> 88800 | L17: =$H$17*L$5 -> 91200 | M17: =$H$17*M$5 -> 102000 | N17: =$H$17*N$5 -> 114000 | O17: =$H$17*O$5 -> 117600 | P17: =$H$17*P$5 -> 120000 | Q17: =$H$17*Q$5 -> 115200 | ... T17: =$H$17*T$5 -> 84000
B18: 4000 | C18: Other (Injuctions, DME, etc.) | D18: Volume | E18: Units | F18: =Assumption!C42 -> 4500 | G18: =Assumption!F42 -> 220 | H18: =Assumption!G42 -> 990000 | I18: =H18*$I$5 -> 69300 | J18: =$H$18*J$5 -> 71280 | K18: =$H$18*K$5 -> 73260 | L18: =$H$18*L$5 -> 75240 | M18: =$H$18*M$5 -> 84150 | N18: =$H$18*N$5 -> 94050 | O18: =$H$18*O$5 -> 97020 | P18: =$H$18*P$5 -> 99000 | Q18: =$H$18*Q$5 -> 95040 | ... T18: =$H$18*T$5 -> 69300
C19: Total Revenue | F19: =SUM(F8:F18) -> 37955 | H19: =SUM(H8:H18) -> 54421400 | I19: =SUM(I8:I18) -> 3809498 | J19: =SUM(J8:J18) -> 3918340.8 | K19: =SUM(K8:K18) -> 4027183.6 | L19: =SUM(L8:L18) -> 4136026.4 | M19: =SUM(M8:M18) -> 4625819 | N19: =SUM(N8:N18) -> 5170033 | O19: =SUM(O8:O18) -> 5333297.2 | ... T19: =SUM(T8:T18) -> 3809498
B21: Salaries
B22: 5100 | C22: Physicians (Surgeons) | D22: FTE | E22: FTE | F22: =Assumption!C49 -> 6 | G22: =Assumption!D49 -> 375000 | H22: =Assumption!E49 -> 2250000 | I22: =$H$22/12 -> 187500 | J22: =$H$22/12 -> 187500 | K22: =$H$22/12 -> 187500 | L22: =$H$22/12 -> 187500 | M22: =$H$22/12 -> 187500 | N22: =$H$22/12 -> 187500 | O22: =$H$22/12 -> 187500 | P22: =$H$22/12 -> 187500 | ... T22: =$H$22/12 -> 187500
B23: 5011 | C23: APPs (NP/PA) | D23: FTE | E23: FTE | F23: =Assumption!C50 -> 4 | G23: =Assumption!D50 -> 140236 | H23: =Assumption!E50 -> 560944 | I23: =$H$23/12 -> 46745.333 | J23: =$H$23/12 -> 46745.333 | K23: =$H$23/12 -> 46745.333 | L23: =$H$23/12 -> 46745.333 | M23: =$H$23/12 -> 46745.333 | N23: =$H$23/12 -> 46745.333 | O23: =$H$23/12 -> 46745.333 | P23: =$H$23/12 -> 46745.333 | ... T23: =$H$23/12 -> 46745.333
B24: 5034 | C24: Nursing (OR + Clinic) | D24: FTE | E24: FTE | F24: =Assumption!C51 -> 16 | G24: =Assumption!D51 -> 85411 | H24: =Assumption!E51 -> 1366576 | I24: =$H$24/12 -> 113881.33 | J24: =$H$24/12 -> 113881.33 | K24: =$H$24/12 -> 113881.33 | L24: =$H$24/12 -> 113881.33 | M24: =$H$24/12 -> 113881.33 | N24: =$H$24/12 -> 113881.33 | O24: =$H$24/12 -> 113881.33 | P24: =$H$24/12 -> 113881.33 | ... T24: =$H$24/12 -> 113881.33
B25: 5311 | C25: Patient Technician | D25: FTE | E25: FTE | F25: =Assumption!C52 -> 5 | G25: =Assumption!D52 -> 55269 | H25: =Assumption!E52 -> 276345 | I25: =$H$25/12 -> 23028.75 | J25: =$H$25/12 -> 23028.75 | K25: =$H$25/12 -> 23028.75 | L25: =$H$25/12 -> 23028.75 | M25: =$H$25/12 -> 23028.75 | N25: =$H$25/12 -> 23028.75 | O25: =$H$25/12 -> 23028.75 | P25: =$H$25/12 -> 23028.75 | ... T25: =$H$25/12 -> 23028.75
B26: 5266 | C26: Medical Assistant | D26: FTE | E26: FTE | F26: =Assumption!C53 -> 5 | G26: =Assumption!D53 -> 62110 | H26: =Assumption!E53 -> 310550 | I26: =$H$26/12 -> 25879.167 | J26: =$H$26/12 -> 25879.167 | K26: =$H$26/12 -> 25879.167 | L26: =$H$26/12 -> 25879.167 | M26: =$H$26/12 -> 25879.167 | N26: =$H$26/12 -> 25879.167 | O26: =$H$26/12 -> 25879.167 | P26: =$H$26/12 -> 25879.167 | ... T26: =$H$26/12 -> 25879.167
B27: 5127 | C27: Front Desk | D27: FTE | E27: FTE | F27: =Assumption!C54 -> 4 | G27: =Assumption!D54 -> 58401 | H27: =Assumption!E54 -> 233604 | I27: =$H$27/12 -> 19467 | J27: =$H$27/12 -> 19467 | K27: =$H$27/12 -> 19467 | L27: =$H$27/12 -> 19467 | M27: =$H$27/12 -> 19467 | N27: =$H$27/12 -> 19467 | O27: =$H$27/12 -> 19467 | P27: =$H$27/12 -> 19467 | ... T27: =$H$27/12 -> 19467
B28: 5601 | C28: Billing/Coding | D28: FTE | E28: FTE | F28: =Assumption!C55 -> 3 | G28: =Assumption!D55 -> 67484 | H28: =Assumption!E55 -> 202452 | I28: =$H$28/12 -> 16871 | J28: =$H$28/12 -> 16871 | K28: =$H$28/12 -> 16871 | L28: =$H$28/12 -> 16871 | M28: =$H$28/12 -> 16871 | N28: =$H$28/12 -> 16871 | O28: =$H$28/12 -> 16871 | P28: =$H$28/12 -> 16871 | ... T28: =$H$28/12 -> 16871
B29: 5010 | C29: Manager | D29: FTE | E29: FTE | F29: =Assumption!C56 -> 1 | G29: =Assumption!D56 -> 110000 | H29: =Assumption!E56 -> 110000 | I29: =$H$29/12 -> 9166.6667 | J29: =$H$29/12 -> 9166.6667 | K29: =$H$29/12 -> 9166.6667 | L29: =$H$29/12 -> 9166.6667 | M29: =$H$29/12 -> 9166.6667 | N29: =$H$29/12 -> 9166.6667 | O29: =$H$29/12 -> 9166.6667 | P29: =$H$29/12 -> 9166.6667 | ... T29: =$H$29/12 -> 9166.6667
B30: 5311 | C30: Financial Analyst | D30: FTE | E30: FTE | F30: =Assumption!C57 -> 1 | G30: =Assumption!D57 -> 98543 | H30: =Assumption!E57 -> 98543 | I30: =$H$30/12 -> 8211.9167 | J30: =$H$30/12 -> 8211.9167 | K30: =$H$30/12 -> 8211.9167 | L30: =$H$30/12 -> 8211.9167 | M30: =$H$30/12 -> 8211.9167 | N30: =$H$30/12 -> 8211.9167 | O30: =$H$30/12 -> 8211.9167 | P30: =$H$30/12 -> 8211.9167 | ... T30: =$H$30/12 -> 8211.9167
B31: 5221 | C31: Overtime & Call Pay | D31: Rate | E31: % of base | G31: =Assumption!D23 -> 0.062 | H31: =G31*Assumption!E58 -> 335358.87 | I31: =$H$31/12 -> 27946.572 | J31: =$H$31/12 -> 27946.572 | K31: =$H$31/12 -> 27946.572 | L31: =$H$31/12 -> 27946.572 | M31: =$H$31/12 -> 27946.572 | N31: =$H$31/12 -> 27946.572 | O31: =$H$31/12 -> 27946.572 | P31: =$H$31/12 -> 27946.572 | ... T31: =$H$31/12 -> 27946.572
B32: 5148 | C32: Agency / Contract Labor | D32: Fixed | E32: annual $ | G32: =Assumption!D24 -> 195000 | H32: =G32 -> 195000 | I32: =$H$32/12 -> 16250 | J32: =$H$32/12 -> 16250 | K32: =$H$32/12 -> 16250 | L32: =$H$32/12 -> 16250 | M32: =$H$32/12 -> 16250 | N32: =$H$32/12 -> 16250 | O32: =$H$32/12 -> 16250 | P32: =$H$32/12 -> 16250 | ... T32: =$H$32/12 -> 16250
B33: 5212 | C33: Employee Benefits | D33: Rate | E33: % of wages+OT | G33: =Assumption!D25 -> 0.22 | H33: =(Assumption!E58+(Assumption!E58*Assumption!D23))*Assumption!D25 -> 1263762 | I33: =$H$33/12 -> 105313.5 | J33: =$H$33/12 -> 105313.5 | K33: =$H$33/12 -> 105313.5 | L33: =$H$33/12 -> 105313.5 | M33: =$H$33/12 -> 105313.5 | N33: =$H$33/12 -> 105313.5 | O33: =$H$33/12 -> 105313.5 | P33: =$H$33/12 -> 105313.5 | ... T33: =$H$33/12 -> 105313.5
B34: 5213 | C34: Payroll Taxes | D34: Rate | E34: % of wages+OT | G34: =Assumption!D26 -> 0.075 | H34: =Assumption!D26*Assumption!E58 -> 405676.05 | I34: =$H$34/12 -> 33806.338 | J34: =$H$34/12 -> 33806.338 | K34: =$H$34/12 -> 33806.338 | L34: =$H$34/12 -> 33806.338 | M34: =$H$34/12 -> 33806.338 | N34: =$H$34/12 -> 33806.338 | O34: =$H$34/12 -> 33806.338 | P34: =$H$34/12 -> 33806.338 | ... T34: =$H$34/12 -> 33806.338
C35: Total Salaries | H35: =SUM(H22:H34) -> 7608810.9 | I35: =SUM(I22:I34) -> 634067.58 | J35: =SUM(J22:J34) -> 634067.58 | K35: =SUM(K22:K34) -> 634067.58 | L35: =SUM(L22:L34) -> 634067.58 | M35: =SUM(M22:M34) -> 634067.58 | N35: =SUM(N22:N34) -> 634067.58 | O35: =SUM(O22:O34) -> 634067.58 | ... T35: =SUM(T22:T34) -> 634067.58
B37: Medical Supplies
C38: Implants & Prosthetics - Arthroplasty | D38: Volume | E38: $/Case | F38: =Assumption!G13 -> 650 | G38: =Assumption!D17 -> 8150 | H38: =G38*F38 -> 5297500 | I38: =$H$38/12 -> 441458.33 | J38: =$H$38/12 -> 441458.33 | K38: =$H$38/12 -> 441458.33 | L38: =$H$38/12 -> 441458.33 | M38: =$H$38/12 -> 441458.33 | N38: =$H$38/12 -> 441458.33 | O38: =$H$38/12 -> 441458.33 | P38: =$H$38/12 -> 441458.33 | ... T38: =$H$38/12 -> 441458.33
C39: Implants/Disposables - Other Procedures | D39: Volume | E39: $/Case | F39: =Assumption!G11-Assumption!G13 -> 2805 | G39: =Assumption!D18 -> 1300 | H39: =G39*F39 -> 3646500 | I39: =$H$39/12 -> 303875 | J39: =$H$39/12 -> 303875 | K39: =$H$39/12 -> 303875 | L39: =$H$39/12 -> 303875 | M39: =$H$39/12 -> 303875 | N39: =$H$39/12 -> 303875 | O39: =$H$39/12 -> 303875 | P39: =$H$39/12 -> 303875 | ... T39: =$H$39/12 -> 303875
C40: Other Surgical Supplies | D40: Volume | E40: $/Case | F40: =Assumption!G11 -> 3455 | G40: =Assumption!D19 -> 385 | H40: =G40*F40 -> 1330175 | I40: =$H$40/12 -> 110847.92 | J40: =$H$40/12 -> 110847.92 | K40: =$H$40/12 -> 110847.92 | L40: =$H$40/12 -> 110847.92 | M40: =$H$40/12 -> 110847.92 | N40: =$H$40/12 -> 110847.92 | O40: =$H$40/12 -> 110847.92 | P40: =$H$40/12 -> 110847.92 | ... T40: =$H$40/12 -> 110847.92
C41: Clinic Medical Supplies | D41: Volume | E41: $/Visit | F41: =Assumption!C40 -> 22000 | G41: =Assumption!D20 -> 15 | H41: =G41*F41 -> 330000 | I41: =$H$41/12 -> 27500 | J41: =$H$41/12 -> 27500 | K41: =$H$41/12 -> 27500 | L41: =$H$41/12 -> 27500 | M41: =$H$41/12 -> 27500 | N41: =$H$41/12 -> 27500 | O41: =$H$41/12 -> 27500 | P41: =$H$41/12 -> 27500 | ... T41: =$H$41/12 -> 27500
C42: Total Medical Supplies | H42: =SUM(H38:H41) -> 10604175 | I42: =SUM(I38:I41) -> 883681.25 | J42: =SUM(J38:J41) -> 883681.25 | K42: =SUM(K38:K41) -> 883681.25 | L42: =SUM(L38:L41) -> 883681.25 | M42: =SUM(M38:M41) -> 883681.25 | N42: =SUM(N38:N41) -> 883681.25 | O42: =SUM(O38:O41) -> 883681.25 | ... T42: =SUM(T38:T41) -> 883681.25
B44: Purchased Services & Overhead
C45: Anesthesia Purchased Services | D45: Volume | E45: $/case | F45: =Assumption!G11 -> 3455 | G45: =Assumption!D9 -> 1240 | H45: =G45*F45 -> 4284200 | I45: =$H$45*I$5 -> 299894 | J45: =$H$45*J$5 -> 308462.4 | K45: =$H$45*K$5 -> 317030.8 | L45: =$H$45*L$5 -> 325599.2 | M45: =$H$45*M$5 -> 364157 | N45: =$H$45*N$5 -> 406999 | O45: =$H$45*O$5 -> 419851.6 | P45: =$H$45*P$5 -> 428420 | ... T45: =$H$45*T$5 -> 299894
C46: Sterile Processing | D46: Volume | E46: annual $ | F46: =Assumption!G11 -> 3455 | G46: =Assumption!D10 -> 390 | H46: =G46*F46 -> 1347450 | I46: =$H$46*I$5 -> 94321.5 | J46: =$H$46*J$5 -> 97016.4 | K46: =$H$46*K$5 -> 99711.3 | L46: =$H$46*L$5 -> 102406.2 | M46: =$H$46*M$5 -> 114533.25 | N46: =$H$46*N$5 -> 128007.75 | O46: =$H$46*O$5 -> 132050.1 | P46: =$H$46*P$5 -> 134745 | ... T46: =$H$46*T$5 -> 94321.5
C47: Radiology Reads | D47: Fixed | E47: Annual $ | G47: =Assumption!D11 -> 120000 | H47: =G47 -> 120000 | I47: =$H$47/12 -> 10000 | J47: =$H$47/12 -> 10000 | K47: =$H$47/12 -> 10000 | L47: =$H$47/12 -> 10000 | M47: =$H$47/12 -> 10000 | N47: =$H$47/12 -> 10000 | O47: =$H$47/12 -> 10000 | P47: =$H$47/12 -> 10000 | ... T47: =$H$47/12 -> 10000
...

Sheet Procedure Margin
B1: Procedure Margin
B4: Baseline Totals From Budget | C4: Values
B5: Total Revenue | C5: ='Detailed Budget'!H19 -> 54421400
B6: Total Operating Expenses | C6: ='Detailed Budget'!H35+'Detailed Budget'!H42+'Detailed Budget'!H53 -> 52674636
B7: Net Operating Income | C7: ='Detailed Budget'!H57 -> 1746763.8
B8: Operating Margin % | C8: ='Detailed Budget'!H58 -> 0.032097002
B10: Surgical Procedures | C10: Volume | D10: Net Rev/Case | E10: Net Rev | F10: Implants/Case | G10: Supplies/Case | H10: Purchased Services/Case | I10: Direct Variable Cost/Case | J10: Total Variable Cost | K10: CM $ | L10: CM % Before Facility Alloc | M10: Faccility Alloc/Case | N10: CM After Alloc | O10: Fully-Loaded Margin
B11: ACL Reconstruction | C11: =Assumption!C31 -> 400 | D11: =Assumption!F31 -> 13930.4 | E11: =Assumption!G31 -> 5572160 | F11: =Assumption!D18 -> 1300 | G11: =Assumption!$D$19 -> 385 | H11: =Assumption!$D$9+Assumption!$D$10 -> 1630 | I11: =F11+G11+H11 -> 3315 | J11: =I11*C11 -> 1326000 | K11: =E11-J11 -> 4246160 | L11: =K11/E11 -> 0.76203124 | M11: =Assumption!$D$7 -> 3000 | N11: =K11-(M11*C11) -> 3046160 | O11: =N11/E11 -> 0.5466749
B12: Total Knee Replacement | C12: =Assumption!C32 -> 300 | D12: =Assumption!F32 -> 25961.2 | E12: =Assumption!G32 -> 7788360 | F12: =Assumption!D17 -> 8150 | G12: =Assumption!$D$19 -> 385 | H12: =Assumption!$D$9+Assumption!$D$10 -> 1630 | I12: =F12+G12+H12 -> 10165 | J12: =I12*C12 -> 3049500 | K12: =E12-J12 -> 4738860 | L12: =K12/E12 -> 0.60845415 | M12: =Assumption!$D$7+Assumption!$D$8 -> 14000 | N12: =K12-(M12*C12) -> 538860 | O12: =N12/E12 -> 0.069187865
B13: Total Hip Replacement | C13: =Assumption!C33 -> 350 | D13: =Assumption!F33 -> 27322.58 | E13: =Assumption!G33 -> 9562903 | F13: =Assumption!D17 -> 8150 | G13: =Assumption!$D$19 -> 385 | H13: =Assumption!$D$9+Assumption!$D$10 -> 1630 | I13: =F13+G13+H13 -> 10165 | J13: =I13*C13 -> 3557750 | K13: =E13-J13 -> 6005153 | L13: =K13/E13 -> 0.62796339 | M13: =Assumption!$D$7+Assumption!$D$8 -> 14000 | N13: =K13-(M13*C13) -> 1105153 | O13: =N13/E13 -> 0.11556669
B14: Arthroscopy (Other) | C14: =Assumption!C34 -> 500 | D14: =Assumption!F34 -> 8896.46 | E14: =Assumption!G34 -> 4448230 | F14: =Assumption!D18 -> 1300 | G14: =Assumption!$D$19 -> 385 | H14: =Assumption!$D$9+Assumption!$D$10 -> 1630 | I14: =F14+G14+H14 -> 3315 | J14: =I14*C14 -> 1657500 | K14: =E14-J14 -> 2790730 | L14: =K14/E14 -> 0.62737988 | M14: =Assumption!$D$7 -> 3000 | N14: =K14-(M14*C14) -> 1290730 | O14: =N14/E14 -> 0.2901671
B15: Rotator Cuff Repair | C15: =Assumption!C35 -> 430 | D15: =Assumption!F35 -> 15006.84 | E15: =Assumption!G35 -> 6452941.2 | F15: =Assumption!D18 -> 1300 | G15: =Assumption!$D$19 -> 385 | H15: =Assumption!$D$9+Assumption!$D$10 -> 1630 | I15: =F15+G15+H15 -> 3315 | J15: =I15*C15 -> 1425450 | K15: =E15-J15 -> 5027491.2 | L15: =K15/E15 -> 0.77910073 | M15: =Assumption!$D$7 -> 3000 | N15: =K15-(M15*C15) -> 3737491.2 | O15: =N15/E15 -> 0.57919189
B16: Fracture Repair | C16: =Assumption!C36 -> 325 | D16: =Assumption!F36 -> 11682.54 | E16: =Assumption!G36 -> 3796825.5 | F16: =Assumption!D18 -> 1300 | G16: =Assumption!$D$19 -> 385 | H16: =Assumption!$D$9+Assumption!$D$10 -> 1630 | I16: =F16+G16+H16 -> 3315 | J16: =I16*C16 -> 1077375 | K16: =E16-J16 -> 2719450.5 | L16: =K16/E16 -> 0.71624321 | M16: =Assumption!$D$7+Assumption!$D$8 -> 14000 | N16: =K16-(M16*C16) -> -1830549.5 | O16: =N16/E16 -> -0.48212632
B17: Carpal Tunnel Release | C17: =Assumption!C37 -> 700 | D17: =Assumption!F37 -> 5398.03 | E17: =Assumption!G37 -> 3778621 | F17: =Assumption!D18 -> 1300 | G17: =Assumption!$D$19 -> 385 | H17: =Assumption!$D$9+Assumption!$D$10 -> 1630 | I17: =F17+G17+H17 -> 3315 | J17: =I17*C17 -> 2320500 | K17: =E17-J17 -> 1458121 | L17: =K17/E17 -> 0.38588707 | M17: =Assumption!$D$7 -> 3000 | N17: =K17-(M17*C17) -> -641879 | O17: =N17/E17 -> -0.16987123
B18: Meniscus Repair | C18: =Assumption!C38 -> 450 | D18: =Assumption!F38 -> 9403.02 | E18: =Assumption!G38 -> 4231359 | F18: =Assumption!D18 -> 1300 | G18: =Assumption!$D$19 -> 385 | H18: =Assumption!$D$9+Assumption!$D$10 -> 1630 | I18: =F18+G18+H18 -> 3315 | J18: =I18*C18 -> 1491750 | K18: =E18-J18 -> 2739609 | L18: =K18/E18 -> 0.64745369 | M18: =Assumption!$D$7 -> 3000 | N18: =K18-(M18*C18) -> 1389609 | O18: =N18/E18 -> 0.32840726
B19: Total | C19: =Assumption!C39 -> 3455 | E19: =SUM(E11:E18) -> 45631400

Sheet Capacity
B1: Capacity
B5: Operating Room Capacity
B7: Procedure | C7: Annual Volume | D7: OR Minutes/Case | E7: Turnover (min) | F7: Total OR Minutes | G7: Total OR Hours
B8: ACL Reconstruction | C8: =Assumption!C31 -> 400 | D8: 85 | E8: ='Analysis Input'!$C$9 -> 20 | F8: =(D8+E8)*C8 -> 42000 | G8: =F8/60 -> 700
B9: Total Knee Replacement | C9: =Assumption!C32 -> 300 | D9: ='Analysis Input'!C20 -> 95 | E9: ='Analysis Input'!$C$9 -> 20 | F9: =(D9+E9)*C9 -> 34500 | G9: =F9/60 -> 575
B10: Total Hip Replacement | C10: =Assumption!C33 -> 350 | D10: ='Analysis Input'!C21 -> 90 | E10: ='Analysis Input'!$C$9 -> 20 | F10: =(D10+E10)*C10 -> 38500 | G10: =F10/60 -> 641.66667
B11: Arthroscopy (Other) | C11: =Assumption!C34 -> 500 | D11: ='Analysis Input'!C22 -> 50 | E11: ='Analysis Input'!$C$9 -> 20 | F11: =(D11+E11)*C11 -> 35000 | G11: =F11/60 -> 583.33333
B12: Rotator Cuff Repair | C12: =Assumption!C35 -> 430 | D12: 80 | E12: ='Analysis Input'!$C$9 -> 20 | F12: =(D12+E12)*C12 -> 43000 | G12: =F12/60 -> 716.66667
B13: Fracture Repair | C13: =Assumption!C36 -> 325 | D13: 55 | E13: ='Analysis Input'!$C$9 -> 20 | F13: =(D13+E13)*C13 -> 24375 | G13: =F13/60 -> 406.25
B14: Carpal Tunnel Release | C14: =Assumption!C37 -> 700 | D14: ='Analysis Input'!C25 -> 40 | E14: ='Analysis Input'!$C$9 -> 20 | F14: =(D14+E14)*C14 -> 42000 | G14: =F14/60 -> 700
B15: Meniscus Repair | C15: =Assumption!C38 -> 450 | D15: ='Analysis Input'!C26 -> 60 | E15: ='Analysis Input'!$C$9 -> 20 | F15: =(D15+E15)*C15 -> 36000 | G15: =F15/60 -> 600
B16: TOTAL | C16: =SUM(C8:C15) -> 3455 | G16: =SUM(G8:G15) -> 4922.9167
B18: Metric | C18: Value
B19: OR Hours Required (Annual) | C19: =G16 -> 4922.9167
B20: OR Hours Available (Annual) | C20: ='Analysis Input'!C7*'Analysis Input'!C8 -> 4500
B21: OR Utilization | C21: =C19/C20 -> 1.0939815
B22: OR Hours Gap (available - required) | C22: =C20-C19 -> -422.91667
B24: Monthly OR Hours
B26: Month | C26: Phasing % | D26: OR Hours Required | E26: OR Hours Available (avg) | F26: Utilization
B27: Jan | C27: =HLOOKUP(B27,Assumption!$F$5:$Q$6,2) -> 0.075 | D27: =C27*$C$19 -> 369.21875 | E27: =$C$20/12 -> 375 | F27: =D27/E27 -> 0.98458333
B28: Feb | C28: =Assumption!G6 -> 0.075 | D28: =C28*$C$19 -> 369.21875 | E28: =$C$20/12 -> 375 | F28: =D28/E28 -> 0.98458333
B29: Mar | C29: =HLOOKUP(B29,Assumption!$F$5:$Q$6,2) -> 0.087 | D29: =C29*$C$19 -> 428.29375 | E29: =$C$20/12 -> 375 | F29: =D29/E29 -> 1.1421167
B30: Apr | C30: =Assumption!I6 -> 0.083 | D30: =C30*$C$19 -> 408.60208 | E30: =$C$20/12 -> 375 | F30: =D30/E30 -> 1.0896056
B31: May | C31: =HLOOKUP(B31,Assumption!$F$5:$Q$6,2) -> 0.087 | D31: =C31*$C$19 -> 428.29375 | E31: =$C$20/12 -> 375 | F31: =D31/E31 -> 1.1421167
B32: Jun | C32: =HLOOKUP(B32,Assumption!$F$5:$Q$6,2) -> 0.086 | D32: =C32*$C$19 -> 423.37083 | E32: =$C$20/12 -> 375 | F32: =D32/E32 -> 1.1289889
B33: Jul | C33: =HLOOKUP(B33,Assumption!$F$5:$Q$6,2) -> 0.075 | D33: =C33*$C$19 -> 369.21875 | E33: =$C$20/12 -> 375 | F33: =D33/E33 -> 0.98458333
B34: Aug | C34: =Assumption!M6 -> 0.087 | D34: =C34*$C$19 -> 428.29375 | E34: =$C$20/12 -> 375 | F34: =D34/E34 -> 1.1421167
B35: Sep | C35: =HLOOKUP(B35,Assumption!$F$5:$Q$6,2) -> 0.084 | D35: =C35*$C$19 -> 413.525 | E35: =$C$20/12 -> 375 | F35: =D35/E35 -> 1.1027333
B36: Oct | C36: =HLOOKUP(B36,Assumption!$F$5:$Q$6,2) -> 0.087 | D36: =C36*$C$19 -> 428.29375 | E36: =$C$20/12 -> 375 | F36: =D36/E36 -> 1.1421167
B37: Nov | C37: =HLOOKUP(B37,Assumption!$F$5:$Q$6,2) -> 0.087 | D37: =C37*$C$19 -> 428.29375 | E37: =$C$20/12 -> 375 | F37: =D37/E37 -> 1.1421167
B38: Dec | C38: =Assumption!Q6 -> 0.072 | D38: =C38*$C$19 -> 354.45 | E38: =$C$20/12 -> 375 | F38: =D38/E38 -> 0.9452
B40: Clinic Capacity
B42: Metric | C42: Value
B43: Annual Clinic Visits (Assumption) | C43: =Assumption!C40 -> 22000
B44: Physician FTE | C44: =Assumption!C49 -> 6
B45: APP FTE | C45: =Assumption!C50 -> 4
B46: Clinic capacity (visits/year) | C46: =((Assumption!C49*'Analysis Input'!C10)+(Assumption!C50*'Analysis Input'!C11))*'Analysis Input'!C12 -> 23520
B47: Capacity utilization | C47: =C43/C46 -> 0.93537415

Sheet Break-Even Analysis
B1: Break-Even Analysis
B5: Variable Costs (From Budget & Assumptions)
B7: Component | C7: Annual $
B8: Arthroplasty implants (TKR+THR) | C8: ='Detailed Budget'!H38 -> 5297500
B9: Other implants/disposables | C9: ='Detailed Budget'!H39 -> 3646500
B10: Other surgical supplies | C10: ='Detailed Budget'!H40 -> 1330175
B11: Clinic supplies | C11: ='Detailed Budget'!H41 -> 330000
B12: Anesthesia purchased services | C12: ='Detailed Budget'!H45 -> 4284200
B13: Other purchased services (variable part only) | C13: =Assumption!G11*Assumption!D10 -> 1347450
B14: OR / PACU allocation | C14: ='Detailed Budget'!H48 -> 15045000
B15: Inpatient unit allocation | C15: ='Detailed Budget'!H49 -> 10725000
B16: Total Variable Cost | C16: =SUM(C8:C15) -> 42005825
B18: Contribution Margin Ratio | C18: Value
B19: Net Revenue | C19: ='Detailed Budget'!H19 -> 54421400
B20: Variable Cost Ratio | C20: =C16/C19 -> 0.77186227
B21: Fixed Cost Ration | C21: =1-C20 -> 0.22813773
B22: Fixed Cost $ | C22: ='Detailed Budget'!H56-C16 -> 10668811
B23: Break-Even Net Revenue | C23: =C22/C21 -> 46764780
B25: Break-even Surgical Cases (Weighted Average) | C25: Value
B26: Total Surgical Cases | C26: =Assumption!G11 -> 3455
B27: Surgical Net Revenue | C27: =Assumption!G39 -> 45631400
B28: Surgical Variable Cost | C28: ='Detailed Budget'!H38+'Detailed Budget'!H39+'Detailed Budget'!H41+'Detailed Budget'!H45+'Detailed Budget'!H46+'Detailed Budget'!H48+'Detailed Budget'!H49 -> 40675650
B29: Net Revenue/Surgical Case | C29: =C27/C26 -> 13207.352
B30: Variable Cost/Surgical Revenue | C30: =C28/C26 -> 11772.981
B31: CM/Surgical Case | C31: =C29-C30 -> 1434.3704
B32: Fixed Cost Allocated To Surgery | C32: =(('Detailed Budget'!H35+'Detailed Budget'!H42+'Detailed Budget'!H53)-'Break-Even Analysis'!C16)*(Assumption!G39/Assumption!G44) -> 8945612.9
B33: Break-Even Surgical Cases | C33: =C32/C31 -> 6236.6129

Sheet Productivity
B1: Workforce Productivity (FTE, Visits, Cases, $/FTE)
B5: Core Volumes & FTE
B7: Metric | C7: Value
B8: Total surgical cases | C8: =Assumption!G11 -> 3455
B9: Total Clinic Visits | C9: =Assumption!C40 -> 22000
B10: Physicians (Surgeons) | C10: =Assumption!C49 -> 6
B11: APPs (NP/PA) | C11: =Assumption!C50 -> 4
B12: Nursing (OR + Clinic) | C12: =Assumption!C51 -> 16
B13: Patient Technician | C13: =Assumption!C52 -> 5
B14: Medical Assistant | C14: =Assumption!C53 -> 5
B15: Front Desk | C15: =Assumption!C54 -> 4
B16: Billing/Coding | C16: =Assumption!C55 -> 3
B17: Manager | C17: =Assumption!C56 -> 1
B18: Financial Analyst | C18: =Assumption!C57 -> 1
B19: Total FTEs | C19: =Assumption!C58 -> 45
B22: Productivity Ratios
B24: Metric | C24: Value
B25: Surgical Cases/Surgeon FTE | C25: =Assumption!G11/Assumption!C49 -> 575.83333
B26: Clinic Visits/Surgeon FTE | C26: =Assumption!C40/Assumption!C49 -> 3666.6667
B27: Clinic visits/APP FTE | C27: =Assumption!C40/Assumption!C50 -> 5500
B28: Clinic Visits/Total Provider FTE (MD+APP) | C28: =Assumption!C40/(Assumption!C49+Assumption!C50) -> 2200
B29: Clinic Visits/Clinic Session (implied) | C29: =Assumption!C40/(('Analysis Input'!C10*Assumption!C49)+(Assumption!C50*'Analysis Input'!C11)) -> 11.22449
B30: OR Hours/Surgeon FTE | C30: =Capacity!C19/Assumption!C49 -> 820.48611
B33: Financial Ratio
B35: Metric | C35: Value
B36: Total net revenue | C36: =Assumption!G44 -> 54421400
B37: Net revenue per surgeon FTE | C37: =Assumption!G44/Assumption!C49 -> 9070233.3
B38: Net revenue per provider FTE (MD+APP) | C38: =Assumption!G44/(Assumption!C49+Assumption!C50) -> 5442140
B39: Total salaries & benefits | C39: ='Detailed Budget'!H35 -> 7608810.9
B40: Salaries & benefits per surgical case | C40: ='Detailed Budget'!H35/Assumption!G11 -> 2202.2608
B41: Salaries & benefits per clinic visit | C41: ='Detailed Budget'!H35/'Detailed Budget'!F16 -> 345.85504
B42: NOI per surgeon FTE | C42: =('Detailed Budget'!H19-'Detailed Budget'!H56)/Assumption!C49 -> 291127.29

Sheet Payor Mix
B1: Payor Mix & Yield Assumptions
B5: Payor | C5: Mix % | D5: Net-ToGross% | E5: Weighted NTG
B6: Medicare | C6: 0.35 | D6: 0.2 | E6: =C6*D6 -> 0.07
B7: Medicaid | C7: 0.07 | D7: 0.12 | E7: =C7*D7 -> 0.0084
B8: Private Insurance | C8: 0.53 | D8: 0.44 | E8: =C8*D8 -> 0.2332
B9: Self-Pay | C9: 0.05 | D9: 0.1 | E9: =C9*D9 -> 0.005
B10: Total | C10: =SUM(C6:C9) -> 1 | E10: =SUM(E6:E9) -> 0.3166
B11: Blended NTG | C11: =E10 -> 0.3166
B14: Surgical Revenue By Payor (Charges-Based)
B15: Total Surgical Gross Charges ($) | C15: =SUMPRODUCT(Assumption!C31:C38,Assumption!D31:D38) -> 144129500
B16: Total Surgical Net Revenue ($) | C16: =Assumption!G39 -> 45631400
B17: Implied Surgical NTG % | C17: =C16/C15 -> 0.3166
B20: Payor | C20: Gross Charges ($) | D20: Net-ToGross % | E20: Net Revenue ($)
B21: Medicare | C21: =C6*$C$15 -> 50445325 | D21: =D6 -> 0.2 | E21: =C21*D21 -> 10089065
B22: Medicaid | C22: =C7*$C$15 -> 10089065 | D22: =D7 -> 0.12 | E22: =C22*D22 -> 1210687.8
B23: Private Insurance | C23: =C8*$C$15 -> 76388635 | D23: =D8 -> 0.44 | E23: =C23*D23 -> 33610999
B24: Self-Pay | C24: =C9*$C$15 -> 7206475 | D24: =D9 -> 0.1 | E24: =C24*D24 -> 720647.5
B25: Total | C25: =SUM(C21:C24) -> 144129500 | E25: =SUM(E21:E24) -> 45631400

Sheet Analysis Input
B1: Analysis Input
B4: Capacity & Productivity Inputs
B6: Input | C6: Value | D6: Units/Notes
B7: OR Block Hours/Week | C7: 90 | D7: Hours/week across all ortho blocks
B8: OR Weeks/Year | C8: 50 | D8: Weeks/year
B9: Avg Turnover Time/Case | C9: 20 | D9: Minutes/case
B10: Clinic Sessions/Provider/Year (MD) | C10: 180 | D10: Sessions/year
B11: Clinic Sessions/Provider/Year (APP) | C11: 220 | D11: Sessions/year
B12: Target Clinic Visits/Session | C12: 12 | D12: Visits/Sessions
B13: Working Days/Year | C13: 340 | D13: Days/year
B16: Case Time (OR minutes, skin-to-skin) by Procedure
B18: Procedure | C18: OR Minutes/Case
B19: ACL Reconstruction | C19: 90
B20: Total Knee Replacement | C20: 95
B21: Total Hip Replacement | C21: 90
B22: Arthroscopy (Other) | C22: 50
B23: Rotator Cuff Repair | C23: 90
B24: Fracture Repair | C24: 60
B25: Carpal Tunnel Release | C25: 40
B26: Meniscus Repair | C26: 60

Sheet Assumption
B1: Assumptions
B4: Cost Assumptions
F5: Jan | G5: Feb | H5: Mar | I5: Apr | J5: May | K5: Jun | L5: Jul | M5: Aug | N5: Sep | O5: Oct | P5: Nov | Q5: Dec
B6: Key Cost Drivers | C6: Driver/Unit | D6: Rate ($) | F6: 0.075 | G6: 0.075 | H6: 0.082 | I6: 0.083 | J6: 0.085 | K6: 0.086 | L6: 0.087 | M6: 0.087 | N6: 0.084 | O6: 0.083 | P6: 0.081 | Q6: 0.072
B7: OR / PACU Allocation | C7: $/Surgical Case | D7: 3000
B8: Inpatient Unit Allocation | C8: $/Inpatient Case | D8: 11000
B9: Anesthesia Purchased Services | C9: $/Surgical Case | D9: 1240
B10: Sterile Processing | C10: $/Surgical Case | D10: 390 | F10: Key Volume Line | G10: Volume
B11: Radiology Reads | C11: Fixed Annual $ | D11: 120000 | F11: Total Surgical Cases | G11: =SUM(C31:C38) -> 3455
B12: Facility Overhead | C12: Fixed Annual $ | D12: 3700000 | F12: Inpatient Cases (TKR+THR+Fracture) | G12: =C32+C33+C36 -> 975
B13: Administrative Overhead | C13: Fixed Annual $ | D13: 2150000 | F13: Arthroplasty Cases (TKR+THR) | G13: =C32+C33 -> 650
B14: Depreciation | C14: Annual $ | D14: 670000
B16: Medical Supplies Cost Drivers | C16: Driver/Unit | D16: Rate ($)
B17: Arthroplasty Implants (TKR+THR) | C17: $/Case | D17: 8150
B18: Other Procedure Implants/Disposables | C18: $/Case | D18: 1300
B19: Other Surgical Supplies | C19: $/Surgical Case | D19: 385
B20: Clinic Supplies | C20: $/Visit | D20: 15
B22: Labor & Add-ons | C22: Driver/Unit | D22: Rate ($)
B23: Overtime & Call Pay | C23: % of Base | D23: 0.062
B24: Agency/Contract Labor | C24: Annual $ | D24: 195000
B25: Employee Benefits | C25: % of Wages + OT | D25: 0.22
B26: Payroll Taxes | C26: % of Wages + OT | D26: 0.075
B28: Revenue Assumptions
B30: Service | C30: Annual Volume | D30: Avg Charge/Unit ($) | E30: Net-To-Gross% | F30: Net Revenue/Unit ($) | G30: Total Net Revenue
B31: ACL Reconstruction | C31: 400 | D31: 44000 | E31: ='Payor Mix'!$C$11 -> 0.3166 | F31: =E31*D31 -> 13930.4 | G31: =F31*C31 -> 5572160
B32: Total Knee Replacement | C32: 300 | D32: 82000 | E32: ='Payor Mix'!$C$11 -> 0.3166 | F32: =E32*D32 -> 25961.2 | G32: =F32*C32 -> 7788360
B33: Total Hip Replacement | C33: 350 | D33: 86300 | E33: ='Payor Mix'!$C$11 -> 0.3166 | F33: =E33*D33 -> 27322.58 | G33: =F33*C33 -> 9562903
B34: Arthroscopy (Other) | C34: 500 | D34: 28100 | E34: ='Payor Mix'!$C$11 -> 0.3166 | F34: =E34*D34 -> 8896.46 | G34: =F34*C34 -> 4448230
B35: Rotator Cuff Repair | C35: 430 | D35: 47400 | E35: ='Payor Mix'!$C$11 -> 0.3166 | F35: =E35*D35 -> 15006.84 | G35: =F35*C35 -> 6452941.2
B36: Fracture Repair | C36: 325 | D36: 36900 | E36: ='Payor Mix'!$C$11 -> 0.3166 | F36: =E36*D36 -> 11682.54 | G36: =F36*C36 -> 3796825.5
B37: Carpal Tunnel Release | C37: 700 | D37: 17050 | E37: ='Payor Mix'!$C$11 -> 0.3166 | F37: =E37*D37 -> 5398.03 | G37: =F37*C37 -> 3778621
B38: Meniscus Repair | C38: 450 | D38: 29700 | E38: ='Payor Mix'!$C$11 -> 0.3166 | F38: =E38*D38 -> 9403.02 | G38: =F38*C38 -> 4231359
B39: Totals for Surgical Services | C39: =SUM(C31:C38) -> 3455 | G39: =SUM(G31:G38) -> 45631400
B40: Clinical Visits | C40: 22000 | F40: 300 | G40: =C40*F40 -> 6600000
B41: Imaging Ancillary (X-ray/US/MRI) | C41: 8000 | F41: 150 | G41: =C41*F41 -> 1200000
B42: Other (Injuctions, DME, etc.) | C42: 4500 | F42: 220 | G42: =C42*F42 -> 990000
B43: Totals For Clinic & Ancillary Services | G43: =SUM(G40:G42) -> 8790000
B44: Total Net Revenue | G44: =G43+G39 -> 54421400
B46: Staffing Assumptions
B48: Position | C48: FTE | D48: Annual Salary/FTE ($) | E48: Total Base Salary ($)
...

Sheet Detail Catalog
B1: Detail Catalog
B4: Item | C4: Notes / Examples
B5: Admin overhead | C5: Finance/HR/legal allocations
B6: Agency/contract labor | C6: Travel nurses, temp staffing
B7: Ancillary revenue | C7: X-ray, ultrasound
B8: Anesthesia services | C8: Purchased/allocated costs
B9: APP salaries | C9: NP/PA
B10: Bad debt & charity | C10: Uncompensated care (if included)
B11: Benefits | C11: Health, retirement, etc.
B12: Clinic revenue | C12: E/M visits, follow-ups
B13: Clinic supplies | C13: Injection supplies, casting materials
B14: Depreciation | C14: Capital equipment depreciation
B15: Facility overhead | C15: Occupancy, IT, utilities, insurance
... B30: Surgical revenue - outpatient | C30: Arthroscopy, ACL, carpal tunnel, etc.
